  0%|          | 0/10 [00:00<?, ?it/s]
  0%|          | 0/1100 [00:00<?, ?it/s][A  0%|          | 0/1100 [00:00<?, ?it/s]
  0%|          | 0/10 [00:00<?, ?it/s]
Traceback (most recent call last):
  File "/cluster/home/yutang/miniconda3/envs/unjam/lib/python3.12/site-packages/networkx/classes/graph.py", line 1357, in neighbors
    return iter(self._adj[n])
                ~~~~~~~~~^^^
KeyError: 10

The above exception was the direct cause of the following exception:

Traceback (most recent call last):
  File "/cluster/home/yutang/unjam-back/power_unit/./test.py", line 229, in <module>
    xData, uData ,yData, uData_dis ,yData_dis,yData_noise= generator.generate_pastdata(X0)
                                                           ^^^^^^^^^^^^^^^^^^^^^^^^^^^^^^^
  File "/cluster/home/yutang/unjam-back/power_unit/generator.py", line 95, in generate_pastdata
    neighbors = sorted(list(self.graph.neighbors(i)))  # Sort neighbors
                            ^^^^^^^^^^^^^^^^^^^^^^^
  File "/cluster/home/yutang/miniconda3/envs/unjam/lib/python3.12/site-packages/networkx/classes/graph.py", line 1359, in neighbors
    raise NetworkXError(f"The node {n} is not in the graph.") from err
networkx.exception.NetworkXError: The node 10 is not in the graph.
